<robot
  name="drrobot_jaguar_description">
  <link
    name="base_footprint">
    <inertial>
      <origin
        xyz="0 0 0"
        rpy="0 0 0" />
      <mass
        value="0.0001" />
      <inertia
        ixx="0.0001"
        ixy="0.0"
        ixz="0.0"
        iyy="0.0001"
        iyz="0.0"
        izz="0.0001" />
    </inertial>
    <visual>
      <origin
        xyz="0 0 0"
        rpy="0 0 0" />
      <geometry>
        <box size="0.001 0.001 0.001" />
      </geometry>
      <material
        name="">
        <color
          rgba="0.64706 0.61961 0.58431 1" />
      </material>
    </visual>
  </link>

  <link
    name="laser">
    <inertial>
      <origin
        xyz="0 0 0"
        rpy="0 0 0" />
      <mass
        value="0.0001" />
      <inertia
        ixx="0.0001"
        ixy="0.0"
        ixz="0.0"
        iyy="0.0001"
        iyz="0.0"
        izz="0.0001" />
    </inertial>
    <visual>
      <origin
        xyz="0 0 0"
        rpy="0 0 0" />
      <geometry>
        <box size="0.001 0.001 0.001" />
      </geometry>
      <material
        name="">
        <color
          rgba="0.64706 0.61961 0.58431 1" />
      </material>
    </visual>
  </link>
<joint
    name="laser_joint"
    type="fixed">
    <origin
      xyz="0.182 0 0.08"
      rpy="0 0 0" />
    <parent
      link="base_link" />
    <child
      link="laser" />
  </joint>

  <link
    name="base_link">
    <inertial>
      <origin
        xyz="-0.00221359785124025 -0.0292579888224023 -0.0024951598946823"
        rpy="0 0 0" />
      <mass
        value="26.13043204203493" />
      <inertia
        ixx="0.0276002632944681"
        ixy="-0.000914692698189266"
        ixz="-0.000840772240971686"
        iyy="0.030763549536253"
        iyz="-0.00131984234245519"
        izz="0.0492606675203303" />
    </inertial>
    <visual>
      <origin
        xyz="0 0 0"
        rpy="0 0 0" />
      <geometry>
        <mesh
          filename="package://drrobot_jaguar_description/meshes/base_link.STL" />
      </geometry>
      <material
        name="">
        <color
          rgba="0.776470588235294 0.756862745098039 0.737254901960784 1" />
      </material>
    </visual>
    <collision>
      <origin
        xyz="0 0 0"
        rpy="0 0 0" />
      <geometry>
        <mesh
          filename="package://drrobot_jaguar_description/meshes/base_link.STL" />
      </geometry>
    </collision>
  </link>


 <joint
    name="base_footprint_joint"
    type="fixed">
    <origin
      xyz="0 0 0.16"
      rpy="0 0 0" />
    <parent
      link="base_footprint" />
    <child
      link="base_link" />
  </joint>

  <link
    name="Wheel_FL">
    <inertial>
      <origin
        xyz="0.0255571013702725 0 -5.55111512312578E-17"
        rpy="0 0 0" />
      <mass
        value="1.01785236539895" />
      <inertia
        ixx="0.0498351948386199"
        ixy="-5.82051814966513E-19"
        ixz="-9.15389267693399E-19"
        iyy="0.0309425807772029"
        iyz="-4.33680868994202E-18"
        izz="0.0309425807772029" />
    </inertial>
    <visual>
      <origin
        xyz="0 0 0"
        rpy="0 0 0" />
      <geometry>
        <mesh
          filename="package://drrobot_jaguar_description/meshes/Wheel_FL.STL" />
      </geometry>
      <material
        name="">
        <color
          rgba="0.294117647058824 0.294117647058824 0.294117647058824 1" />
      </material>
    </visual>
    <collision>
      <origin
        xyz="0 0 0"
        rpy="0 0 0" />
      <geometry>
        <mesh
          filename="package://drrobot_jaguar_description/meshes/Wheel_FL.STL" />
      </geometry>
    </collision>
  </link>
  <joint
    name="Joint_FL"
    type="continuous">
    <origin
      xyz="0.20027 0.2698 -0.038046"
      rpy="-1.8468 -6.123E-17 -1.5708" />
    <parent
      link="base_link" />
    <child
      link="Wheel_FL" />
    <axis
      xyz="-1 0 0" />
  </joint>
  <link
    name="Wheel_FR">
    <inertial>
      <origin
        xyz="0.0140413640731467 0 -5.55111512312578E-17"
        rpy="0 0 0" />
      <mass
        value="1.01785236539895" />
      <inertia
        ixx="0.0498351948386199"
        ixy="9.00217946897549E-19"
        ixz="2.19866532783779E-19"
        iyy="0.0310055842319982"
        iyz="0"
        izz="0.0310055842319983" />
    </inertial>
    <visual>
      <origin
        xyz="0 0 0"
        rpy="0 0 0" />
      <geometry>
        <mesh
          filename="package://drrobot_jaguar_description/meshes/Wheel_FR.STL" />
      </geometry>
      <material
        name="">
        <color
          rgba="0.294117647058824 0.294117647058824 0.294117647058824 1" />
      </material>
    </visual>
    <collision>
      <origin
        xyz="0 0 0"
        rpy="0 0 0" />
      <geometry>
        <mesh
          filename="package://drrobot_jaguar_description/meshes/Wheel_FR.STL" />
      </geometry>
    </collision>
  </link>
  <joint
    name="Joint_FR"
    type="continuous">
    <origin
      xyz="0.20027 -0.23063 -0.038046"
      rpy="-1.572 -6.123E-17 -1.5708" />
    <parent
      link="base_link" />
    <child
      link="Wheel_FR" />
    <axis
      xyz="-1 0 0" />
  </joint>
  <link
    name="Wheel_RR">
    <inertial>
      <origin
        xyz="0.0140977657024902 -1.38777878078145E-17 2.77555756156289E-17"
        rpy="0 0 0" />
      <mass
        value="1.01785236539896" />
      <inertia
        ixx="0.0498351948386199"
        ixy="-8.35270082805769E-19"
        ixz="-7.24989206083506E-19"
        iyy="0.0309378902983738"
        iyz="0"
        izz="0.0309378902983738" />
    </inertial>
    <visual>
      <origin
        xyz="0 0 0"
        rpy="0 0 0" />
      <geometry>
        <mesh
          filename="package://drrobot_jaguar_description/meshes/Wheel_RR.STL" />
      </geometry>
      <material
        name="">
        <color
          rgba="0.294117647058824 0.294117647058824 0.294117647058824 1" />
      </material>
    </visual>
    <collision>
      <origin
        xyz="0 0 0"
        rpy="0 0 0" />
      <geometry>
        <mesh
          filename="package://drrobot_jaguar_description/meshes/Wheel_RR.STL" />
      </geometry>
    </collision>
  </link>
  <joint
    name="Joint_RR"
    type="continuous">
    <origin
      xyz="-0.1502 -0.22993 -0.038179"
      rpy="-1.7446 -6.123E-17 -1.5708" />
    <parent
      link="base_link" />
    <child
      link="Wheel_RR" />
    <axis
      xyz="-1 0 0" />
  </joint>
  <link
    name="Wheel_RL">
    <inertial>
      <origin
        xyz="0.0257210773307773 -6.93889390390723E-18 2.77555756156289E-17"
        rpy="0 0 0" />
      <mass
        value="1.01785236539896" />
      <inertia
        ixx="0.0498351948386199"
        ixy="-3.60551519238553E-20"
        ixz="-1.38767699104207E-18"
        iyy="0.0309537657552617"
        iyz="-4.33680868994202E-19"
        izz="0.0309537657552617" />
    </inertial>
    <visual>
      <origin
        xyz="0 0 0"
        rpy="0 0 0" />
      <geometry>
        <mesh
          filename="package://drrobot_jaguar_description/meshes/Wheel_RL.STL" />
      </geometry>
      <material
        name="">
        <color
          rgba="0.294117647058824 0.294117647058824 0.294117647058824 1" />
      </material>
    </visual>
    <collision>
      <origin
        xyz="0 0 0"
        rpy="0 0 0" />
      <geometry>
        <mesh
          filename="package://drrobot_jaguar_description/meshes/Wheel_RL.STL" />
      </geometry>
    </collision>
  </link>
  <joint
    name="Joint_RL"
    type="continuous">
    <origin
      xyz="-0.1502 0.27033 -0.038179"
      rpy="-1.5934 -6.123E-17 -1.5708" />
    <parent
      link="base_link" />
    <child
      link="Wheel_RL" />
    <axis
      xyz="-1 0 0" />
  </joint>
</robot>
